ERROR:root:127.0.0.1 2018-12-01
ERROR:root:127.0.0.1 2018-12-01
ERROR:root:127.0.0.1 2018-12-01
ERROR:root:127.0.0.1 2018-12-01
ERROR:root:127.0.0.1 2018-12-01
ERROR:root:127.0.0.1 2018-12-01
ERROR:root:127.0.0.1 2018-12-01
ERROR:root:127.0.0.1 2018-12-01
ERROR:root:127.0.0.1 2018-12-01
ERROR:root:127.0.0.1 2018-12-01
ERROR:root:127.0.0.1 2018-12-01
ERROR:root:127.0.0.1 2018-12-01
ERROR:root:127.0.0.1 2018-12-01
ERROR:root:127.0.0.1 2018-12-01
ERROR:root:127.0.0.1 2018-12-01
ERROR:root:127.0.0.1 2018-12-01
ERROR:root:127.0.0.1 2018-12-01
ERROR:root:127.0.0.1 2018-12-01
ERROR:root:127.0.0.1 2018-12-01
ERROR:root:127.0.0.1 2018-12-01
ERROR:root:127.0.0.1 2018-12-01
ERROR:root:127.0.0.1 2018-12-01
ERROR:root:127.0.0.1 2018-12-01
ERROR:root:127.0.0.1 2018-12-01
ERROR:root:127.0.0.1 2018-12-01
ERROR:root:127.0.0.1 2018-12-01
ERROR:root:127.0.0.1 2018-12-01
ERROR:root:127.0.0.1 2018-12-01
ERROR:root:127.0.0.1 2018-12-01
ERROR:root:127.0.0.1 2018-12-01
ERROR:root:127.0.0.1 2018-12-01
ERROR:root:127.0.0.1 2018-12-01
ERROR:root:127.0.0.1 2018-12-01
ERROR:root:127.0.0.1 2018-12-01
ERROR:root:127.0.0.1 2018-12-01
ERROR:root:127.0.0.1 2018-12-01
ERROR:root:127.0.0.1 2018-12-01
ERROR:root:127.0.0.1 2018-12-01
ERROR:root:127.0.0.1 2018-12-01
ERROR:root:127.0.0.1 2018-12-01
ERROR:root:127.0.0.1 2018-12-01
ERROR:root:127.0.0.1 2018-12-01
ERROR:root:127.0.0.1 2018-12-01
ERROR:root:127.0.0.1 2018-12-01
ERROR:root:127.0.0.1 2018-12-01
ERROR:root:127.0.0.1 2018-12-01
ERROR:root:127.0.0.1 2018-12-01
ERROR:root:127.0.0.1 2018-12-01
ERROR:root:127.0.0.1 2018-12-01
ERROR:root:127.0.0.1 2018-12-01
ERROR:root:127.0.0.1 2018-12-01
ERROR:root:127.0.0.1 2018-12-01
ERROR:root:127.0.0.1 2018-12-01
ERROR:root:127.0.0.1 2018-12-01
ERROR:root:127.0.0.1 2018-12-01
ERROR:root:127.0.0.1 2018-12-01
ERROR:root:127.0.0.1 2018-12-01
ERROR:root:127.0.0.1 2018-12-01
ERROR:root:127.0.0.1 2018-12-01
ERROR:root:127.0.0.1 2018-12-01
ERROR:root:127.0.0.1 2018-12-01
ERROR:root:127.0.0.1 2018-12-01
ERROR:root:127.0.0.1 2018-12-01
ERROR:root:127.0.0.1 2018-12-01
ERROR:root:127.0.0.1 2018-12-01
ERROR:root:127.0.0.1 2018-12-01
ERROR:root:127.0.0.1 2018-12-01
ERROR:root:127.0.0.1 2018-12-01
ERROR:root:127.0.0.1 2018-12-01
ERROR:root:127.0.0.1 2018-12-01
ERROR:root:127.0.0.1 2018-12-01
ERROR:root:127.0.0.1 2018-12-01
ERROR:root:127.0.0.1 2018-12-01
ERROR:root:127.0.0.1 2018-12-01
ERROR:root:127.0.0.1 2018-12-01
ERROR:root:127.0.0.1 2018-12-01
ERROR:root:127.0.0.1 2018-12-01
ERROR:root:127.0.0.1 2018-12-01
ERROR:root:127.0.0.1 2018-12-01
ERROR:root:127.0.0.1 2018-12-01
ERROR:root:127.0.0.1 2018-12-01
ERROR:root:127.0.0.1 2018-12-01
ERROR:root:127.0.0.1 2018-12-01
ERROR:root:127.0.0.1 2018-12-01
ERROR:root:127.0.0.1 2018-12-01
ERROR:root:127.0.0.1 2018-12-01
ERROR:root:127.0.0.1 2018-12-01
ERROR:root:127.0.0.1 2018-12-01
ERROR:root:127.0.0.1 2018-12-01
ERROR:root:127.0.0.1 2018-12-01
ERROR:root:127.0.0.1 2018-12-01
ERROR:root:127.0.0.1 2018-12-01
ERROR:root:127.0.0.1 2018-12-01
ERROR:root:127.0.0.1 2018-12-01
ERROR:root:127.0.0.1 2018-12-01
ERROR:root:127.0.0.1 2018-12-01
ERROR:root:127.0.0.1 2018-12-01
ERROR:root:127.0.0.1 2018-12-01
ERROR:root:127.0.0.1 2018-12-01
ERROR:root:127.0.0.1 2018-12-01
ERROR:root:127.0.0.1 2018-12-01
ERROR:root:127.0.0.1 2018-12-01
ERROR:root:127.0.0.1 2018-12-01
ERROR:root:127.0.0.1 2018-12-01
ERROR:root:127.0.0.1 2018-12-01
ERROR:root:127.0.0.1 2018-12-01
ERROR:flask.app:Exception on /get_database_search [GET]
Traceback (most recent call last):
  File "C:\Users\Iago Caitano\AppData\Local\Programs\Python\Python37-32\lib\site-packages\flask\app.py", line 2292, in wsgi_app
    response = self.full_dispatch_request()
  File "C:\Users\Iago Caitano\AppData\Local\Programs\Python\Python37-32\lib\site-packages\flask\app.py", line 1815, in full_dispatch_request
    rv = self.handle_user_exception(e)
  File "C:\Users\Iago Caitano\AppData\Local\Programs\Python\Python37-32\lib\site-packages\flask\app.py", line 1718, in handle_user_exception
    reraise(exc_type, exc_value, tb)
  File "C:\Users\Iago Caitano\AppData\Local\Programs\Python\Python37-32\lib\site-packages\flask\_compat.py", line 35, in reraise
    raise value
  File "C:\Users\Iago Caitano\AppData\Local\Programs\Python\Python37-32\lib\site-packages\flask\app.py", line 1813, in full_dispatch_request
    rv = self.dispatch_request()
  File "C:\Users\Iago Caitano\AppData\Local\Programs\Python\Python37-32\lib\site-packages\flask\app.py", line 1799, in dispatch_request
    return self.view_functions[rule.endpoint](**req.view_args)
  File "server.py", line 99, in get_database_search
    return jsonify(process_json(data, params_dict['globe'] == "countries", date, params_dict['disease']))
  File "C:\Users\Iago Caitano\Documents\GitHub\georreferenciamento-centeias\db_request.py", line 37, in process_json
    for result in data:
TypeError: 'NoneType' object is not iterable
ERROR:flask.app:Exception on /get_database_search [GET]
Traceback (most recent call last):
  File "C:\Users\Iago Caitano\AppData\Local\Programs\Python\Python37-32\lib\site-packages\flask\app.py", line 2292, in wsgi_app
    response = self.full_dispatch_request()
  File "C:\Users\Iago Caitano\AppData\Local\Programs\Python\Python37-32\lib\site-packages\flask\app.py", line 1815, in full_dispatch_request
    rv = self.handle_user_exception(e)
  File "C:\Users\Iago Caitano\AppData\Local\Programs\Python\Python37-32\lib\site-packages\flask\app.py", line 1718, in handle_user_exception
    reraise(exc_type, exc_value, tb)
  File "C:\Users\Iago Caitano\AppData\Local\Programs\Python\Python37-32\lib\site-packages\flask\_compat.py", line 35, in reraise
    raise value
  File "C:\Users\Iago Caitano\AppData\Local\Programs\Python\Python37-32\lib\site-packages\flask\app.py", line 1813, in full_dispatch_request
    rv = self.dispatch_request()
  File "C:\Users\Iago Caitano\AppData\Local\Programs\Python\Python37-32\lib\site-packages\flask\app.py", line 1799, in dispatch_request
    return self.view_functions[rule.endpoint](**req.view_args)
  File "server.py", line 99, in get_database_search
    return jsonify(process_json(data, params_dict['globe'] == "countries", date, params_dict['disease']))
  File "C:\Users\Iago Caitano\Documents\GitHub\georreferenciamento-centeias\db_request.py", line 37, in process_json
    for result in data:
TypeError: 'NoneType' object is not iterable
ERROR:flask.app:Exception on /get_database_search [GET]
Traceback (most recent call last):
  File "C:\Users\Iago Caitano\AppData\Local\Programs\Python\Python37-32\lib\site-packages\flask\app.py", line 2292, in wsgi_app
    response = self.full_dispatch_request()
  File "C:\Users\Iago Caitano\AppData\Local\Programs\Python\Python37-32\lib\site-packages\flask\app.py", line 1815, in full_dispatch_request
    rv = self.handle_user_exception(e)
  File "C:\Users\Iago Caitano\AppData\Local\Programs\Python\Python37-32\lib\site-packages\flask\app.py", line 1718, in handle_user_exception
    reraise(exc_type, exc_value, tb)
  File "C:\Users\Iago Caitano\AppData\Local\Programs\Python\Python37-32\lib\site-packages\flask\_compat.py", line 35, in reraise
    raise value
  File "C:\Users\Iago Caitano\AppData\Local\Programs\Python\Python37-32\lib\site-packages\flask\app.py", line 1813, in full_dispatch_request
    rv = self.dispatch_request()
  File "C:\Users\Iago Caitano\AppData\Local\Programs\Python\Python37-32\lib\site-packages\flask\app.py", line 1799, in dispatch_request
    return self.view_functions[rule.endpoint](**req.view_args)
  File "server.py", line 99, in get_database_search
    return jsonify(process_json(data, params_dict['globe'] == "countries", date, params_dict['disease']))
  File "C:\Users\Iago Caitano\Documents\GitHub\georreferenciamento-centeias\db_request.py", line 37, in process_json
    for result in data:
TypeError: 'NoneType' object is not iterable
ERROR:root:127.0.0.1 2018-12-01
ERROR:flask.app:Exception on /get_database_search [GET]
Traceback (most recent call last):
  File "C:\Users\Iago Caitano\AppData\Local\Programs\Python\Python37-32\lib\site-packages\flask\app.py", line 2292, in wsgi_app
    response = self.full_dispatch_request()
  File "C:\Users\Iago Caitano\AppData\Local\Programs\Python\Python37-32\lib\site-packages\flask\app.py", line 1815, in full_dispatch_request
    rv = self.handle_user_exception(e)
  File "C:\Users\Iago Caitano\AppData\Local\Programs\Python\Python37-32\lib\site-packages\flask\app.py", line 1718, in handle_user_exception
    reraise(exc_type, exc_value, tb)
  File "C:\Users\Iago Caitano\AppData\Local\Programs\Python\Python37-32\lib\site-packages\flask\_compat.py", line 35, in reraise
    raise value
  File "C:\Users\Iago Caitano\AppData\Local\Programs\Python\Python37-32\lib\site-packages\flask\app.py", line 1813, in full_dispatch_request
    rv = self.dispatch_request()
  File "C:\Users\Iago Caitano\AppData\Local\Programs\Python\Python37-32\lib\site-packages\flask\app.py", line 1799, in dispatch_request
    return self.view_functions[rule.endpoint](**req.view_args)
  File "server.py", line 99, in get_database_search
    return jsonify(process_json(data, params_dict['globe'] == "countries", date, params_dict['disease']))
  File "C:\Users\Iago Caitano\Documents\GitHub\georreferenciamento-centeias\db_request.py", line 37, in process_json
    for result in data:
TypeError: 'NoneType' object is not iterable
ERROR:root:127.0.0.1 2018-12-01
ERROR:flask.app:Exception on /get_database_search [GET]
Traceback (most recent call last):
  File "C:\Users\Iago Caitano\AppData\Local\Programs\Python\Python37-32\lib\site-packages\flask\app.py", line 2292, in wsgi_app
    response = self.full_dispatch_request()
  File "C:\Users\Iago Caitano\AppData\Local\Programs\Python\Python37-32\lib\site-packages\flask\app.py", line 1815, in full_dispatch_request
    rv = self.handle_user_exception(e)
  File "C:\Users\Iago Caitano\AppData\Local\Programs\Python\Python37-32\lib\site-packages\flask\app.py", line 1718, in handle_user_exception
    reraise(exc_type, exc_value, tb)
  File "C:\Users\Iago Caitano\AppData\Local\Programs\Python\Python37-32\lib\site-packages\flask\_compat.py", line 35, in reraise
    raise value
  File "C:\Users\Iago Caitano\AppData\Local\Programs\Python\Python37-32\lib\site-packages\flask\app.py", line 1813, in full_dispatch_request
    rv = self.dispatch_request()
  File "C:\Users\Iago Caitano\AppData\Local\Programs\Python\Python37-32\lib\site-packages\flask\app.py", line 1799, in dispatch_request
    return self.view_functions[rule.endpoint](**req.view_args)
  File "server.py", line 99, in get_database_search
    return jsonify(process_json(data, params_dict['globe'] == "countries", date, params_dict['disease']))
  File "C:\Users\Iago Caitano\Documents\GitHub\georreferenciamento-centeias\db_request.py", line 37, in process_json
    for result in data:
TypeError: 'NoneType' object is not iterable
ERROR:flask.app:Exception on /get_database_search [GET]
Traceback (most recent call last):
  File "C:\Users\Iago Caitano\AppData\Local\Programs\Python\Python37-32\lib\site-packages\flask\app.py", line 2292, in wsgi_app
    response = self.full_dispatch_request()
  File "C:\Users\Iago Caitano\AppData\Local\Programs\Python\Python37-32\lib\site-packages\flask\app.py", line 1815, in full_dispatch_request
    rv = self.handle_user_exception(e)
  File "C:\Users\Iago Caitano\AppData\Local\Programs\Python\Python37-32\lib\site-packages\flask\app.py", line 1718, in handle_user_exception
    reraise(exc_type, exc_value, tb)
  File "C:\Users\Iago Caitano\AppData\Local\Programs\Python\Python37-32\lib\site-packages\flask\_compat.py", line 35, in reraise
    raise value
  File "C:\Users\Iago Caitano\AppData\Local\Programs\Python\Python37-32\lib\site-packages\flask\app.py", line 1813, in full_dispatch_request
    rv = self.dispatch_request()
  File "C:\Users\Iago Caitano\AppData\Local\Programs\Python\Python37-32\lib\site-packages\flask\app.py", line 1799, in dispatch_request
    return self.view_functions[rule.endpoint](**req.view_args)
  File "server.py", line 99, in get_database_search
    return jsonify(process_json(data, params_dict['globe'] == "countries", date, params_dict['disease']))
  File "C:\Users\Iago Caitano\Documents\GitHub\georreferenciamento-centeias\db_request.py", line 37, in process_json
    for result in data:
TypeError: 'NoneType' object is not iterable
ERROR:flask.app:Exception on /get_database_search [GET]
Traceback (most recent call last):
  File "C:\Users\Iago Caitano\AppData\Local\Programs\Python\Python37-32\lib\site-packages\flask\app.py", line 2292, in wsgi_app
    response = self.full_dispatch_request()
  File "C:\Users\Iago Caitano\AppData\Local\Programs\Python\Python37-32\lib\site-packages\flask\app.py", line 1815, in full_dispatch_request
    rv = self.handle_user_exception(e)
  File "C:\Users\Iago Caitano\AppData\Local\Programs\Python\Python37-32\lib\site-packages\flask\app.py", line 1718, in handle_user_exception
    reraise(exc_type, exc_value, tb)
  File "C:\Users\Iago Caitano\AppData\Local\Programs\Python\Python37-32\lib\site-packages\flask\_compat.py", line 35, in reraise
    raise value
  File "C:\Users\Iago Caitano\AppData\Local\Programs\Python\Python37-32\lib\site-packages\flask\app.py", line 1813, in full_dispatch_request
    rv = self.dispatch_request()
  File "C:\Users\Iago Caitano\AppData\Local\Programs\Python\Python37-32\lib\site-packages\flask\app.py", line 1799, in dispatch_request
    return self.view_functions[rule.endpoint](**req.view_args)
  File "server.py", line 99, in get_database_search
    return jsonify(process_json(data, params_dict['globe'] == "countries", date, params_dict['disease']))
  File "C:\Users\Iago Caitano\Documents\GitHub\georreferenciamento-centeias\db_request.py", line 37, in process_json
    for result in data:
TypeError: 'NoneType' object is not iterable
