ERROR:root:192.168.5.107 2018-11-26
ERROR:flask.app:Exception on /get_database_search [GET]
Traceback (most recent call last):
  File "/usr/local/lib/python3.6/dist-packages/flask/app.py", line 2292, in wsgi_app
    response = self.full_dispatch_request()
  File "/usr/local/lib/python3.6/dist-packages/flask/app.py", line 1815, in full_dispatch_request
    rv = self.handle_user_exception(e)
  File "/usr/local/lib/python3.6/dist-packages/flask/app.py", line 1718, in handle_user_exception
    reraise(exc_type, exc_value, tb)
  File "/usr/local/lib/python3.6/dist-packages/flask/_compat.py", line 35, in reraise
    raise value
  File "/usr/local/lib/python3.6/dist-packages/flask/app.py", line 1813, in full_dispatch_request
    rv = self.dispatch_request()
  File "/usr/local/lib/python3.6/dist-packages/flask/app.py", line 1799, in dispatch_request
    return self.view_functions[rule.endpoint](**req.view_args)
  File "server.py", line 88, in get_database_search
    return jsonify(process_json(data, params_dict['globe'] == "countries", date))
UnboundLocalError: local variable 'date' referenced before assignment
ERROR:flask.app:Exception on /get_database_search [GET]
Traceback (most recent call last):
  File "/usr/local/lib/python3.6/dist-packages/flask/app.py", line 2292, in wsgi_app
    response = self.full_dispatch_request()
  File "/usr/local/lib/python3.6/dist-packages/flask/app.py", line 1815, in full_dispatch_request
    rv = self.handle_user_exception(e)
  File "/usr/local/lib/python3.6/dist-packages/flask/app.py", line 1718, in handle_user_exception
    reraise(exc_type, exc_value, tb)
  File "/usr/local/lib/python3.6/dist-packages/flask/_compat.py", line 35, in reraise
    raise value
  File "/usr/local/lib/python3.6/dist-packages/flask/app.py", line 1813, in full_dispatch_request
    rv = self.dispatch_request()
  File "/usr/local/lib/python3.6/dist-packages/flask/app.py", line 1799, in dispatch_request
    return self.view_functions[rule.endpoint](**req.view_args)
  File "server.py", line 88, in get_database_search
    return jsonify(process_json(data, params_dict['globe'] == "countries", date))
UnboundLocalError: local variable 'date' referenced before assignment
ERROR:flask.app:Exception on /get_database_search [GET]
Traceback (most recent call last):
  File "/usr/local/lib/python3.6/dist-packages/flask/app.py", line 2292, in wsgi_app
    response = self.full_dispatch_request()
  File "/usr/local/lib/python3.6/dist-packages/flask/app.py", line 1815, in full_dispatch_request
    rv = self.handle_user_exception(e)
  File "/usr/local/lib/python3.6/dist-packages/flask/app.py", line 1718, in handle_user_exception
    reraise(exc_type, exc_value, tb)
  File "/usr/local/lib/python3.6/dist-packages/flask/_compat.py", line 35, in reraise
    raise value
  File "/usr/local/lib/python3.6/dist-packages/flask/app.py", line 1813, in full_dispatch_request
    rv = self.dispatch_request()
  File "/usr/local/lib/python3.6/dist-packages/flask/app.py", line 1799, in dispatch_request
    return self.view_functions[rule.endpoint](**req.view_args)
  File "server.py", line 88, in get_database_search
    return jsonify(process_json(data, params_dict['globe'] == "countries", date))
  File "/home/leo/programa/georreferenciamento-centeias/db_request.py", line 30, in process_json
    for result in data:
TypeError: 'NoneType' object is not iterable
ERROR:flask.app:Exception on /get_database_search [GET]
Traceback (most recent call last):
  File "/usr/local/lib/python3.6/dist-packages/flask/app.py", line 2292, in wsgi_app
    response = self.full_dispatch_request()
  File "/usr/local/lib/python3.6/dist-packages/flask/app.py", line 1815, in full_dispatch_request
    rv = self.handle_user_exception(e)
  File "/usr/local/lib/python3.6/dist-packages/flask/app.py", line 1718, in handle_user_exception
    reraise(exc_type, exc_value, tb)
  File "/usr/local/lib/python3.6/dist-packages/flask/_compat.py", line 35, in reraise
    raise value
  File "/usr/local/lib/python3.6/dist-packages/flask/app.py", line 1813, in full_dispatch_request
    rv = self.dispatch_request()
  File "/usr/local/lib/python3.6/dist-packages/flask/app.py", line 1799, in dispatch_request
    return self.view_functions[rule.endpoint](**req.view_args)
  File "server.py", line 88, in get_database_search
    return jsonify(process_json(data, params_dict['globe'] == "countries", date))
  File "/home/leo/programa/georreferenciamento-centeias/db_request.py", line 30, in process_json
    for result in data:
TypeError: 'NoneType' object is not iterable
ERROR:flask.app:Exception on /get_database_search [GET]
Traceback (most recent call last):
  File "/usr/local/lib/python3.6/dist-packages/flask/app.py", line 2292, in wsgi_app
    response = self.full_dispatch_request()
  File "/usr/local/lib/python3.6/dist-packages/flask/app.py", line 1815, in full_dispatch_request
    rv = self.handle_user_exception(e)
  File "/usr/local/lib/python3.6/dist-packages/flask/app.py", line 1718, in handle_user_exception
    reraise(exc_type, exc_value, tb)
  File "/usr/local/lib/python3.6/dist-packages/flask/_compat.py", line 35, in reraise
    raise value
  File "/usr/local/lib/python3.6/dist-packages/flask/app.py", line 1813, in full_dispatch_request
    rv = self.dispatch_request()
  File "/usr/local/lib/python3.6/dist-packages/flask/app.py", line 1799, in dispatch_request
    return self.view_functions[rule.endpoint](**req.view_args)
  File "server.py", line 88, in get_database_search
    return jsonify(process_json(data, params_dict['globe'] == "countries", date))
  File "/home/leo/programa/georreferenciamento-centeias/db_request.py", line 30, in process_json
    for result in data:
TypeError: 'NoneType' object is not iterable
ERROR:flask.app:Exception on /get_database_search [GET]
Traceback (most recent call last):
  File "/usr/local/lib/python3.6/dist-packages/flask/app.py", line 2292, in wsgi_app
    response = self.full_dispatch_request()
  File "/usr/local/lib/python3.6/dist-packages/flask/app.py", line 1815, in full_dispatch_request
    rv = self.handle_user_exception(e)
  File "/usr/local/lib/python3.6/dist-packages/flask/app.py", line 1718, in handle_user_exception
    reraise(exc_type, exc_value, tb)
  File "/usr/local/lib/python3.6/dist-packages/flask/_compat.py", line 35, in reraise
    raise value
  File "/usr/local/lib/python3.6/dist-packages/flask/app.py", line 1813, in full_dispatch_request
    rv = self.dispatch_request()
  File "/usr/local/lib/python3.6/dist-packages/flask/app.py", line 1799, in dispatch_request
    return self.view_functions[rule.endpoint](**req.view_args)
  File "server.py", line 88, in get_database_search
    return jsonify(process_json(data, params_dict['globe'] == "countries", date))
  File "/home/leo/programa/georreferenciamento-centeias/db_request.py", line 30, in process_json
    for result in data:
TypeError: 'NoneType' object is not iterable
ERROR:root:192.168.5.107 2018-11-26
ERROR:flask.app:Exception on /get_database_search [GET]
Traceback (most recent call last):
  File "/usr/local/lib/python3.6/dist-packages/flask/app.py", line 2292, in wsgi_app
    response = self.full_dispatch_request()
  File "/usr/local/lib/python3.6/dist-packages/flask/app.py", line 1815, in full_dispatch_request
    rv = self.handle_user_exception(e)
  File "/usr/local/lib/python3.6/dist-packages/flask/app.py", line 1718, in handle_user_exception
    reraise(exc_type, exc_value, tb)
  File "/usr/local/lib/python3.6/dist-packages/flask/_compat.py", line 35, in reraise
    raise value
  File "/usr/local/lib/python3.6/dist-packages/flask/app.py", line 1813, in full_dispatch_request
    rv = self.dispatch_request()
  File "/usr/local/lib/python3.6/dist-packages/flask/app.py", line 1799, in dispatch_request
    return self.view_functions[rule.endpoint](**req.view_args)
  File "server.py", line 88, in get_database_search
    return jsonify(process_json(data, params_dict['globe'] == "countries", date))
  File "/home/leo/programa/georreferenciamento-centeias/db_request.py", line 30, in process_json
    for result in data:
TypeError: 'NoneType' object is not iterable
ERROR:root:127.0.0.1 2018-11-27
ERROR:root:127.0.0.1 2018-11-27
ERROR:root:127.0.0.1 2018-11-27
ERROR:root:127.0.0.1 2018-11-27
ERROR:root:127.0.0.1 2018-11-27
ERROR:root:127.0.0.1 2018-11-27
ERROR:flask.app:Exception on /get_database_search [GET]
Traceback (most recent call last):
  File "/usr/local/lib/python3.6/dist-packages/flask/app.py", line 2292, in wsgi_app
    response = self.full_dispatch_request()
  File "/usr/local/lib/python3.6/dist-packages/flask/app.py", line 1815, in full_dispatch_request
    rv = self.handle_user_exception(e)
  File "/usr/local/lib/python3.6/dist-packages/flask/app.py", line 1718, in handle_user_exception
    reraise(exc_type, exc_value, tb)
  File "/usr/local/lib/python3.6/dist-packages/flask/_compat.py", line 35, in reraise
    raise value
  File "/usr/local/lib/python3.6/dist-packages/flask/app.py", line 1813, in full_dispatch_request
    rv = self.dispatch_request()
  File "/usr/local/lib/python3.6/dist-packages/flask/app.py", line 1799, in dispatch_request
    return self.view_functions[rule.endpoint](**req.view_args)
  File "server.py", line 89, in get_database_search
    print(process_json(data, params_dict['globe'] == "countries", date))
  File "/home/leo/programa/georreferenciamento-centeias/db_request.py", line 53, in process_json
    print(data['url'])
TypeError: list indices must be integers or slices, not str
ERROR:root:127.0.0.1 2018-11-27
ERROR:flask.app:Exception on /get_database_search [GET]
Traceback (most recent call last):
  File "/usr/local/lib/python3.6/dist-packages/flask/app.py", line 2292, in wsgi_app
    response = self.full_dispatch_request()
  File "/usr/local/lib/python3.6/dist-packages/flask/app.py", line 1815, in full_dispatch_request
    rv = self.handle_user_exception(e)
  File "/usr/local/lib/python3.6/dist-packages/flask/app.py", line 1718, in handle_user_exception
    reraise(exc_type, exc_value, tb)
  File "/usr/local/lib/python3.6/dist-packages/flask/_compat.py", line 35, in reraise
    raise value
  File "/usr/local/lib/python3.6/dist-packages/flask/app.py", line 1813, in full_dispatch_request
    rv = self.dispatch_request()
  File "/usr/local/lib/python3.6/dist-packages/flask/app.py", line 1799, in dispatch_request
    return self.view_functions[rule.endpoint](**req.view_args)
  File "server.py", line 89, in get_database_search
    print(process_json(data, params_dict['globe'] == "countries", date))
  File "/home/leo/programa/georreferenciamento-centeias/db_request.py", line 53, in process_json
    print(data['url'])
TypeError: list indices must be integers or slices, not str
ERROR:flask.app:Exception on /get_database_search [GET]
Traceback (most recent call last):
  File "/usr/local/lib/python3.6/dist-packages/flask/app.py", line 2292, in wsgi_app
    response = self.full_dispatch_request()
  File "/usr/local/lib/python3.6/dist-packages/flask/app.py", line 1815, in full_dispatch_request
    rv = self.handle_user_exception(e)
  File "/usr/local/lib/python3.6/dist-packages/flask/app.py", line 1718, in handle_user_exception
    reraise(exc_type, exc_value, tb)
  File "/usr/local/lib/python3.6/dist-packages/flask/_compat.py", line 35, in reraise
    raise value
  File "/usr/local/lib/python3.6/dist-packages/flask/app.py", line 1813, in full_dispatch_request
    rv = self.dispatch_request()
  File "/usr/local/lib/python3.6/dist-packages/flask/app.py", line 1799, in dispatch_request
    return self.view_functions[rule.endpoint](**req.view_args)
  File "server.py", line 89, in get_database_search
    print(process_json(data, params_dict['globe'] == "countries", date))
  File "/home/leo/programa/georreferenciamento-centeias/db_request.py", line 53, in process_json
    print(data['url'])
TypeError: list indices must be integers or slices, not str
ERROR:flask.app:Exception on /get_database_search [GET]
Traceback (most recent call last):
  File "/usr/local/lib/python3.6/dist-packages/flask/app.py", line 2292, in wsgi_app
    response = self.full_dispatch_request()
  File "/usr/local/lib/python3.6/dist-packages/flask/app.py", line 1815, in full_dispatch_request
    rv = self.handle_user_exception(e)
  File "/usr/local/lib/python3.6/dist-packages/flask/app.py", line 1718, in handle_user_exception
    reraise(exc_type, exc_value, tb)
  File "/usr/local/lib/python3.6/dist-packages/flask/_compat.py", line 35, in reraise
    raise value
  File "/usr/local/lib/python3.6/dist-packages/flask/app.py", line 1813, in full_dispatch_request
    rv = self.dispatch_request()
  File "/usr/local/lib/python3.6/dist-packages/flask/app.py", line 1799, in dispatch_request
    return self.view_functions[rule.endpoint](**req.view_args)
  File "server.py", line 89, in get_database_search
    print(process_json(data, params_dict['globe'] == "countries", date))
  File "/home/leo/programa/georreferenciamento-centeias/db_request.py", line 53, in process_json
    print(data['url'])
TypeError: list indices must be integers or slices, not str
ERROR:flask.app:Exception on /get_database_search [GET]
Traceback (most recent call last):
  File "/usr/local/lib/python3.6/dist-packages/flask/app.py", line 2292, in wsgi_app
    response = self.full_dispatch_request()
  File "/usr/local/lib/python3.6/dist-packages/flask/app.py", line 1815, in full_dispatch_request
    rv = self.handle_user_exception(e)
  File "/usr/local/lib/python3.6/dist-packages/flask/app.py", line 1718, in handle_user_exception
    reraise(exc_type, exc_value, tb)
  File "/usr/local/lib/python3.6/dist-packages/flask/_compat.py", line 35, in reraise
    raise value
  File "/usr/local/lib/python3.6/dist-packages/flask/app.py", line 1813, in full_dispatch_request
    rv = self.dispatch_request()
  File "/usr/local/lib/python3.6/dist-packages/flask/app.py", line 1799, in dispatch_request
    return self.view_functions[rule.endpoint](**req.view_args)
  File "server.py", line 89, in get_database_search
    print(process_json(data, params_dict['globe'] == "countries", date))
  File "/home/leo/programa/georreferenciamento-centeias/db_request.py", line 53, in process_json
    print(data['url'])
TypeError: list indices must be integers or slices, not str
ERROR:flask.app:Exception on /get_database_search [GET]
Traceback (most recent call last):
  File "/usr/local/lib/python3.6/dist-packages/flask/app.py", line 2292, in wsgi_app
    response = self.full_dispatch_request()
  File "/usr/local/lib/python3.6/dist-packages/flask/app.py", line 1815, in full_dispatch_request
    rv = self.handle_user_exception(e)
  File "/usr/local/lib/python3.6/dist-packages/flask/app.py", line 1718, in handle_user_exception
    reraise(exc_type, exc_value, tb)
  File "/usr/local/lib/python3.6/dist-packages/flask/_compat.py", line 35, in reraise
    raise value
  File "/usr/local/lib/python3.6/dist-packages/flask/app.py", line 1813, in full_dispatch_request
    rv = self.dispatch_request()
  File "/usr/local/lib/python3.6/dist-packages/flask/app.py", line 1799, in dispatch_request
    return self.view_functions[rule.endpoint](**req.view_args)
  File "server.py", line 89, in get_database_search
    print(process_json(data, params_dict['globe'] == "countries", date))
  File "/home/leo/programa/georreferenciamento-centeias/db_request.py", line 53, in process_json
    print(data['url'])
TypeError: list indices must be integers or slices, not str
ERROR:root:127.0.0.1 2018-11-27
ERROR:root:127.0.0.1 2018-11-27
ERROR:root:127.0.0.1 2018-11-27
